<?xml version="1.0" ?>
<robot name="advanced_quadrotor">
  <!-- ============================================================
       MATERIALS
       ============================================================ -->
  <material name="black">
    <color rgba="0 0 0 1"/>
  </material>
  <material name="silver">
    <color rgba="0.7 0.7 0.7 1"/>
  </material>
  <material name="red">
    <color rgba="1 0 0 1"/>
  </material>
  <material name="transparent">
    <color rgba="0.8 0.8 0.8 0.5"/>
  </material>
  <material name="gray">
    <color rgba="0.5 0.5 0.5 1"/>
  </material>
  <material name="blue">
    <color rgba="0 0 1 1"/>
  </material>
  <material name="green">
    <color rgba="0 1 0 1"/>
  </material>

  <!-- ============================================================
       BASE LINK (Frame approximated as a box)
       ============================================================ -->
  <link name="base_link">
    <visual>
      <geometry>
        <box size="0.3 0.3 0.03"/>
      </geometry>
      <material name="black"/>
    </visual>
    <collision>
      <geometry>
        <box size="0.3 0.3 0.03"/>
      </geometry>
      <surface>
        <contact>
          <ode>
            <mu>0.8</mu>
            <mu2>0.8</mu2>
          </ode>
        </contact>
      </surface>
    </collision>
    <inertial>
      <mass value="0.5"/>
      <inertia ixx="0.00177" ixy="0" ixz="0" iyy="0.00177" iyz="0" izz="0.00333"/>
    </inertial>
  </link>

  <!-- ============================================================
       MOTORS (Approximated as small cylinders)
       ============================================================ -->
  <link name="motor1">
    <visual>
      <geometry>
        <cylinder length="0.02" radius="0.01"/>
      </geometry>
      <material name="silver"/>
    </visual>
    <collision>
      <geometry>
        <cylinder length="0.02" radius="0.01"/>
      </geometry>
    </collision>
    <inertial>
      <mass value="0.05"/>
      <inertia ixx="1.54e-05" ixy="0" ixz="0" iyy="1.54e-05" iyz="0" izz="0.00001"/>
    </inertial>
  </link>
  <joint name="motor1_joint" type="fixed">
    <parent link="base_link"/>
    <child link="motor1"/>
    <origin xyz="0.1414 0.1414 0" rpy="0 0 0"/>
  </joint>

  <link name="motor2">
    <visual>
      <geometry>
        <cylinder length="0.02" radius="0.01"/>
      </geometry>
      <material name="silver"/>
    </visual>
    <collision>
      <geometry>
        <cylinder length="0.02" radius="0.01"/>
      </geometry>
    </collision>
    <inertial>
      <mass value="0.05"/>
      <inertia ixx="1.54e-05" ixy="0" ixz="0" iyy="1.54e-05" iyz="0" izz="0.00001"/>
    </inertial>
  </link>
  <joint name="motor2_joint" type="fixed">
    <parent link="base_link"/>
    <child link="motor2"/>
    <origin xyz="0.1414 -0.1414 0" rpy="0 0 0"/>
  </joint>

  <link name="motor3">
    <visual>
      <geometry>
        <cylinder length="0.02" radius="0.01"/>
      </geometry>
      <material name="silver"/>
    </visual>
    <collision>
      <geometry>
        <cylinder length="0.02" radius="0.01"/>
      </geometry>
    </collision>
    <inertial>
      <mass value="0.05"/>
      <inertia ixx="1.54e-05" ixy="0" ixz="0" iyy="1.54e-05" iyz="0" izz="0.00001"/>
    </inertial>
  </link>
  <joint name="motor3_joint" type="fixed">
    <parent link="base_link"/>
    <child link="motor3"/>
    <origin xyz="-0.1414 0.1414 0" rpy="0 0 0"/>
  </joint>

  <link name="motor4">
    <visual>
      <geometry>
        <cylinder length="0.02" radius="0.01"/>
      </geometry>
      <material name="silver"/>
    </visual>
    <collision>
      <geometry>
        <cylinder length="0.02" radius="0.01"/>
      </geometry>
    </collision>
    <inertial>
      <mass value="0.05"/>
      <inertia ixx="1.54e-05" ixy="0" ixz="0" iyy="1.54e-05" iyz="0" izz="0.00001"/>
    </inertial>
  </link>
  <joint name="motor4_joint" type="fixed">
    <parent link="base_link"/>
    <child link="motor4"/>
    <origin xyz="-0.1414 -0.1414 0" rpy="0 0 0"/>
  </joint>

  <!-- ============================================================
       PROPELLERS (Approximated as thin cylinders)
       ============================================================ -->
  <link name="propeller1">
    <visual>
      <geometry>
        <cylinder length="0.001" radius="0.06"/>
      </geometry>
      <material name="transparent"/>
    </visual>
    <collision>
      <geometry>
        <cylinder length="0.001" radius="0.06"/>
      </geometry>
    </collision>
    <inertial>
      <mass value="0.01"/>
      <inertia ixx="2.5e-05" iyy="2.5e-05" izz="5e-05" ixy="0" ixz="0" iyz="0"/>
    </inertial>
  </link>
  <joint name="propeller1_joint" type="continuous">
    <parent link="motor1"/>
    <child link="propeller1"/>
    <origin xyz="0 0 0.025" rpy="0 0 0"/>
    <axis xyz="0 0 1"/>
    <limit velocity="1000" effort="1"/>
  </joint>

  <link name="propeller2">
    <visual>
      <geometry>
        <cylinder length="0.001" radius="0.06"/>
      </geometry>
      <material name="transparent"/>
    </visual>
    <collision>
      <geometry>
        <cylinder length="0.001" radius="0.06"/>
      </geometry>
    </collision>
    <inertial>
      <mass value="0.01"/>
      <inertia ixx="2.5e-05" iyy="2.5e-05" izz="5e-05" ixy="0" ixz="0" iyz="0"/>
    </inertial>
  </link>
  <joint name="propeller2_joint" type="continuous">
    <parent link="motor2"/>
    <child link="propeller2"/>
    <origin xyz="0 0 0.025" rpy="0 0 0"/>
    <axis xyz="0 0 1"/>
    <limit velocity="1000" effort="1"/>
  </joint>

  <link name="propeller3">
    <visual>
      <geometry>
        <cylinder length="0.001" radius="0.06"/>
      </geometry>
      <material name="transparent"/>
    </visual>
    <collision>
      <geometry>
        <cylinder length="0.001" radius="0.06"/>
      </geometry>
    </collision>
    <inertial>
      <mass value="0.01"/>
      <inertia ixx="2.5e-05" iyy="2.5e-05" izz="5e-05" ixy="0" ixz="0" iyz="0"/>
    </inertial>
  </link>
  <joint name="propeller3_joint" type="continuous">
    <parent link="motor3"/>
    <child link="propeller3"/>
    <origin xyz="0 0 0.025" rpy="0 0 0"/>
    <axis xyz="0 0 1"/>
    <limit velocity="1000" effort="1"/>
  </joint>

  <link name="propeller4">
    <visual>
      <geometry>
        <cylinder length="0.001" radius="0.06"/>
      </geometry>
      <material name="transparent"/>
    </visual>
    <collision>
      <geometry>
        <cylinder length="0.001" radius="0.06"/>
      </geometry>
    </collision>
    <inertial>
      <mass value="0.01"/>
      <inertia ixx="2.5e-05" iyy="2.5e-05" izz="5e-05" ixy="0" ixz="0" iyz="0"/>
    </inertial>
  </link>
  <joint name="propeller4_joint" type="continuous">
    <parent link="motor4"/>
    <child link="propeller4"/>
    <origin xyz="0 0 0.025" rpy="0 0 0"/>
    <axis xyz="0 0 1"/>
    <limit velocity="1000" effort="1"/>
  </joint>

  <!-- ============================================================
       ESCs (Kept as small boxes)
       ============================================================ -->
  <link name="esc1">
    <visual>
      <geometry>
        <box size="0.03 0.02 0.01"/>
      </geometry>
      <material name="red"/>
    </visual>
    <collision>
      <geometry>
        <box size="0.03 0.02 0.01"/>
      </geometry>
    </collision>
    <inertial>
      <mass value="0.01"/>
      <inertia ixx="0.000000833" iyy="0.0000005" izz="0.000000333" ixy="0" ixz="0" iyz="0"/>
    </inertial>
  </link>
  <joint name="esc1_joint" type="fixed">
    <parent link="base_link"/>
    <child link="esc1"/>
    <origin xyz="0.1 0.1 -0.02" rpy="0 0 0"/>
  </joint>

  <link name="esc2">
    <visual>
      <geometry>
        <box size="0.03 0.02 0.01"/>
      </geometry>
      <material name="red"/>
    </visual>
    <collision>
      <geometry>
        <box size="0.03 0.02 0.01"/>
      </geometry>
    </collision>
    <inertial>
      <mass value="0.01"/>
      <inertia ixx="0.000000833" iyy="0.0000005" izz="0.000000333" ixy="0" ixz="0" iyz="0"/>
    </inertial>
  </link>
  <joint name="esc2_joint" type="fixed">
    <parent link="base_link"/>
    <child link="esc2"/>
    <origin xyz="0.1 -0.1 -0.02" rpy="0 0 0"/>
  </joint>

  <link name="esc3">
    <visual>
      <geometry>
        <box size="0.03 0.02 0.01"/>
      </geometry>
      <material name="red"/>
    </visual>
    <collision>
      <geometry>
        <box size="0.03 0.02 0.01"/>
      </geometry>
    </collision>
    <inertial>
      <mass value="0.01"/>
      <inertia ixx="0.000000833" iyy="0.0000005" izz="0.000000333" ixy="0" ixz="0" iyz="0"/>
    </inertial>
  </link>
  <joint name="esc3_joint" type="fixed">
    <parent link="base_link"/>
    <child link="esc3"/>
    <origin xyz="-0.1 0.1 -0.02" rpy="0 0 0"/>
  </joint>

  <link name="esc4">
    <visual>
      <geometry>
        <box size="0.03 0.02 0.01"/>
      </geometry>
      <material name="red"/>
    </visual>
    <collision>
      <geometry>
        <box size="0.03 0.02 0.01"/>
      </geometry>
    </collision>
    <inertial>
      <mass value="0.01"/>
      <inertia ixx="0.000000833" iyy="0.0000005" izz="0.000000333" ixy="0" ixz="0" iyz="0"/>
    </inertial>
  </link>
  <joint name="esc4_joint" type="fixed">
    <parent link="base_link"/>
    <child link="esc4"/>
    <origin xyz="-0.1 -0.1 -0.02" rpy="0 0 0"/>
  </joint>

  <!-- ============================================================
       GUARDS (Approximated as thin disks)
       ============================================================ -->
  <link name="guard1">
    <visual>
      <geometry>
        <cylinder length="0.001" radius="0.18"/>
      </geometry>
      <material name="black"/>
    </visual>
    <collision>
      <geometry>
        <cylinder length="0.001" radius="0.18"/>
      </geometry>
    </collision>
    <inertial>
      <mass value="0.02"/>
      <inertia ixx="0.0001" iyy="0.0001" izz="0.0001" ixy="0" ixz="0" iyz="0"/>
    </inertial>
  </link>
  <joint name="guard1_joint" type="fixed">
    <parent link="base_link"/>
    <child link="guard1"/>
    <origin xyz="0.1414 0.1414 0" rpy="0 0 0"/>
  </joint>

  <link name="guard2">
    <visual>
      <geometry>
        <cylinder length="0.001" radius="0.18"/>
      </geometry>
      <material name="black"/>
    </visual>
    <collision>
      <geometry>
        <cylinder length="0.001" radius="0.18"/>
      </geometry>
    </collision>
    <inertial>
      <mass value="0.02"/>
      <inertia ixx="0.0001" iyy="0.0001" izz="0.0001" ixy="0" ixz="0" iyz="0"/>
    </inertial>
  </link>
  <joint name="guard2_joint" type="fixed">
    <parent link="base_link"/>
    <child link="guard2"/>
    <origin xyz="0.1414 -0.1414 0" rpy="0 0 0"/>
  </joint>

  <link name="guard3">
    <visual>
      <geometry>
        <cylinder length="0.001" radius="0.18"/>
      </geometry>
      <material name="black"/>
    </visual>
    <collision>
      <geometry>
        <cylinder length="0.001" radius="0.18"/>
      </geometry>
    </collision>
    <inertial>
      <mass value="0.02"/>
      <inertia ixx="0.0001" iyy="0.0001" izz="0.0001" ixy="0" ixz="0" iyz="0"/>
    </inertial>
  </link>
  <joint name="guard3_joint" type="fixed">
    <parent link="base_link"/>
    <child link="guard3"/>
    <origin xyz="-0.1414 0.1414 0" rpy="0 0 0"/>
  </joint>

  <link name="guard4">
    <visual>
      <geometry>
        <cylinder length="0.001" radius="0.18"/>
      </geometry>
      <material name="black"/>
    </visual>
    <collision>
      <geometry>
        <cylinder length="0.001" radius="0.18"/>
      </geometry>
    </collision>
    <inertial>
      <mass value="0.02"/>
      <inertia ixx="0.0001" iyy="0.0001" izz="0.0001" ixy="0" ixz="0" iyz="0"/>
    </inertial>
  </link>
  <joint name="guard4_joint" type="fixed">
    <parent link="base_link"/>
    <child link="guard4"/>
    <origin xyz="-0.1414 -0.1414 0" rpy="0 0 0"/>
  </joint>

  <!-- ============================================================
       BATTERY (Box)
       ============================================================ -->
  <link name="battery">
    <visual>
      <geometry>
        <box size="0.1 0.05 0.02"/>
      </geometry>
      <material name="blue"/>
    </visual>
    <collision>
      <geometry>
        <box size="0.1 0.05 0.02"/>
      </geometry>
    </collision>
    <inertial>
      <mass value="0.3"/>
      <inertia ixx="0.000125" iyy="0.000225" izz="0.000275" ixy="0" ixz="0" iyz="0"/>
    </inertial>
  </link>
  <joint name="battery_joint" type="fixed">
    <parent link="base_link"/>
    <child link="battery"/>
    <origin xyz="0 0 -0.03" rpy="0 0 0"/>
  </joint>

  <!-- ============================================================
       FLIGHT CONTROLLER (Box) WITH VIBRATION-DAMPING
       ============================================================ -->
  <link name="fc_mount">
    <visual>
      <geometry>
        <box size="0.05 0.05 0.005"/>
      </geometry>
      <material name="gray"/>
    </visual>
    <collision>
      <geometry>
        <box size="0.05 0.05 0.005"/>
      </geometry>
    </collision>
    <inertial>
      <mass value="0.005"/>
      <inertia ixx="0.000000104" iyy="0.000000104" izz="0.000000104" ixy="0" ixz="0" iyz="0"/>
    </inertial>
  </link>
  <joint name="fc_prismatic_joint" type="prismatic">
    <parent link="base_link"/>
    <child link="fc_mount"/>
    <origin xyz="0 0 0.01" rpy="0 0 0"/>
    <axis xyz="0 0 1"/>
    <limit lower="-0.005" upper="0.005" velocity="0.1" effort="10"/>
    <dynamics damping="5" friction="0.1"/>
  </joint>

  <link name="flight_controller">
    <visual>
      <geometry>
        <box size="0.05 0.05 0.005"/>
      </geometry>
      <material name="green"/>
    </visual>
    <collision>
      <geometry>
        <box size="0.05 0.05 0.005"/>
      </geometry>
    </collision>
    <inertial>
      <mass value="0.02"/>
      <inertia ixx="0.00000833" iyy="0.00000833" izz="0.0000167" ixy="0" ixz="0" iyz="0"/>
    </inertial>
  </link>
  <joint name="fc_joint" type="fixed">
    <parent link="fc_mount"/>
    <child link="flight_controller"/>
    <origin xyz="0 0 0" rpy="0 0 0"/>
  </joint>

  <!-- ============================================================
       2-AXIS GIMBAL (Cylinders) + CAMERA (Box)
       ============================================================ -->
  <link name="gimbal_roll">
    <visual>
      <geometry>
        <cylinder length="0.05" radius="0.01"/>
      </geometry>
      <material name="gray"/>
    </visual>
    <collision>
      <geometry>
        <cylinder length="0.05" radius="0.01"/>
      </geometry>
    </collision>
    <inertial>
      <mass value="0.01"/>
      <inertia ixx="0.000002083" iyy="0.000002083" izz="0.00000125" ixy="0" ixz="0" iyz="0"/>
    </inertial>
  </link>
  <joint name="gimbal_roll_joint" type="revolute">
    <parent link="base_link"/>
    <child link="gimbal_roll"/>
    <origin xyz="0 0 -0.05" rpy="0 0 0"/>
    <axis xyz="1 0 0"/>
    <limit lower="-0.785" upper="0.785" velocity="10" effort="1"/>
    <dynamics damping="0.1" friction="0.01"/>
  </joint>

  <link name="gimbal_pitch">
    <visual>
      <geometry>
        <cylinder length="0.05" radius="0.01"/>
      </geometry>
      <material name="gray"/>
    </visual>
    <collision>
      <geometry>
        <cylinder length="0.05" radius="0.01"/>
      </geometry>
    </collision>
    <inertial>
      <mass value="0.01"/>
      <inertia ixx="0.000002083" iyy="0.000002083" izz="0.00000125" ixy="0" ixz="0" iyz="0"/>
    </inertial>
  </link>
  <joint name="gimbal_pitch_joint" type="revolute">
    <parent link="gimbal_roll"/>
    <child link="gimbal_pitch"/>
    <origin xyz="0 0 -0.025" rpy="0 0 0"/>
    <axis xyz="0 1 0"/>
    <limit lower="-0.785" upper="0.785" velocity="10" effort="1"/>
    <dynamics damping="0.1" friction="0.01"/>
  </joint>

  <link name="camera_link">
    <visual>
      <geometry>
        <box size="0.02 0.02 0.02"/>
      </geometry>
      <material name="black"/>
    </visual>
    <collision>
      <geometry>
        <box size="0.02 0.02 0.02"/>
      </geometry>
    </collision>
    <inertial>
      <mass value="0.03"/>
      <inertia ixx="0.00001" iyy="0.00001" izz="0.00001" ixy="0" ixz="0" iyz="0"/>
    </inertial>
  </link>
  <joint name="camera_joint" type="fixed">
    <parent link="gimbal_pitch"/>
    <child link="camera_link"/>
    <origin xyz="0 0 -0.025" rpy="0 0 0"/>
  </joint>

  <!-- ============================================================
       LANDING GEAR (Cylinders)
       ============================================================ -->
  <link name="leg1">
    <visual>
      <geometry>
        <cylinder length="0.1" radius="0.005"/>
      </geometry>
      <material name="black"/>
    </visual>
    <collision>
      <geometry>
        <cylinder length="0.1" radius="0.005"/>
      </geometry>
    </collision>
    <inertial>
      <mass value="0.01"/>
      <inertia ixx="0.00000833" iyy="0.00000833" izz="0.000000125" ixy="0" ixz="0" iyz="0"/>
    </inertial>
  </link>
  <joint name="leg1_joint" type="fixed">
    <parent link="base_link"/>
    <child link="leg1"/>
    <origin xyz="0.15 0.15 -0.05" rpy="0 0 0"/>
  </joint>

  <link name="leg2">
    <visual>
      <geometry>
        <cylinder length="0.1" radius="0.005"/>
      </geometry>
      <material name="black"/>
    </visual>
    <collision>
      <geometry>
        <cylinder length="0.1" radius="0.005"/>
      </geometry>
    </collision>
    <inertial>
      <mass value="0.01"/>
      <inertia ixx="0.00000833" iyy="0.00000833" izz="0.000000125" ixy="0" ixz="0" iyz="0"/>
    </inertial>
  </link>
  <joint name="leg2_joint" type="fixed">
    <parent link="base_link"/>
    <child link="leg2"/>
    <origin xyz="-0.15 0.15 -0.05" rpy="0 0 0"/>
  </joint>

  <link name="leg3">
    <visual>
      <geometry>
        <cylinder length="0.1" radius="0.005"/>
      </geometry>
      <material name="black"/>
    </visual>
    <collision>
      <geometry>
        <cylinder length="0.1" radius="0.005"/>
      </geometry>
    </collision>
    <inertial>
      <mass value="0.01"/>
      <inertia ixx="0.00000833" iyy="0.00000833" izz="0.000000125" ixy="0" ixz="0" iyz="0"/>
    </inertial>
  </link>
  <joint name="leg3_joint" type="fixed">
    <parent link="base_link"/>
    <child link="leg3"/>
    <origin xyz="-0.15 -0.15 -0.05" rpy="0 0 0"/>
  </joint>

  <link name="leg4">
    <visual>
      <geometry>
        <cylinder length="0.1" radius="0.005"/>
      </geometry>
      <material name="black"/>
    </visual>
    <collision>
      <geometry>
        <cylinder length="0.1" radius="0.005"/>
      </geometry>
    </collision>
    <inertial>
      <mass value="0.01"/>
      <inertia ixx="0.00000833" iyy="0.00000833" izz="0.000000125" ixy="0" ixz="0" iyz="0"/>
    </inertial>
  </link>
  <joint name="leg4_joint" type="fixed">
    <parent link="base_link"/>
    <child link="leg4"/>
    <origin xyz="0.15 -0.15 -0.05" rpy="0 0 0"/>
  </joint>

  <!-- ============================================================
       ANTENNA (Cylinder)
       ============================================================ -->
  <link name="antenna">
    <visual>
      <geometry>
        <cylinder length="0.1" radius="0.001"/>
      </geometry>
      <material name="silver"/>
    </visual>
    <collision>
      <geometry>
        <cylinder length="0.1" radius="0.001"/>
      </geometry>
    </collision>
    <inertial>
      <mass value="0.001"/>
      <inertia ixx="0.000000833" iyy="0.000000833" izz="0.000000001" ixy="0" ixz="0" iyz="0"/>
    </inertial>
  </link>
  <joint name="antenna_joint" type="fixed">
    <parent link="base_link"/>
    <child link="antenna"/>
    <origin xyz="0 0 0.05" rpy="0 0 0"/>
  </joint>

  <!-- ============================================================
       LIDAR (Cylinder)
       ============================================================ -->
  <link name="lidar_link">
    <visual>
      <geometry>
        <cylinder length="0.05" radius="0.02"/>
      </geometry>
      <material name="green"/>
    </visual>
    <collision>
      <geometry>
        <cylinder length="0.05" radius="0.02"/>
      </geometry>
    </collision>
    <inertial>
      <mass value="0.1"/>
      <inertia ixx="0.000025" iyy="0.000025" izz="0.00005" ixy="0" ixz="0" iyz="0"/>
    </inertial>
  </link>
  <joint name="lidar_joint" type="fixed">
    <parent link="base_link"/>
    <child link="lidar_link"/>
    <origin xyz="0 0.1 0" rpy="0 0 0"/>
  </joint>

  <!-- ============================================================
       GAZEBO SENSORS
       ============================================================ -->
  <!-- IMU, GPS, Magnetometer on Flight Controller -->
  <gazebo reference="flight_controller">
    <sensor name="imu_sensor" type="imu">
      <always_on>true</always_on>
      <update_rate>100</update_rate>
      <imu>
        <noise>
          <type>gaussian</type>
          <rate>
            <mean>0</mean>
            <stddev>0.0002</stddev>
          </rate>
          <accel>
            <mean>0</mean>
            <stddev>0.001</stddev>
          </accel>
        </noise>
      </imu>
    </sensor>
    <sensor name="gps_sensor" type="gps">
      <always_on>true</always_on>
      <update_rate>10</update_rate>
      <gps>
        <position_sensing>
          <horizontal>
            <noise type="gaussian">
              <mean>0</mean>
              <stddev>0.5</stddev>
            </noise>
          </horizontal>
          <vertical>
            <noise type="gaussian">
              <mean>0</mean>
              <stddev>1.0</stddev>
            </noise>
          </vertical>
        </position_sensing>
      </gps>
    </sensor>
    <sensor name="mag_sensor" type="magnetometer">
      <always_on>true</always_on>
      <update_rate>50</update_rate>
      <magnetometer>
        <noise>
          <type>gaussian</type>
          <mean>0</mean>
          <stddev>0.005</stddev>
        </noise>
      </magnetometer>
    </sensor>
  </gazebo>

  <!-- Camera Sensor on camera_link -->
  <gazebo reference="camera_link">
    <sensor name="camera_sensor" type="camera">
      <always_on>true</always_on>
      <update_rate>30</update_rate>
      <camera>
        <horizontal_fov>1.57</horizontal_fov>
        <image>
          <width>640</width>
          <height>480</height>
          <format>R8G8B8</format>
        </image>
        <clip>
          <near>0.1</near>
          <far>100</far>
        </clip>
        <noise>
          <type>gaussian</type>
          <mean>0</mean>
          <stddev>0.007</stddev>
        </noise>
        <distortion>
          <k1>0.1</k1>
          <k2>0.01</k2>
          <k3>0.001</k3>
          <p1>0.001</p1>
          <p2>0.001</p2>
        </distortion>
      </camera>
    </sensor>
  </gazebo>

  <!-- Lidar Sensor on lidar_link -->
  <gazebo reference="lidar_link">
    <sensor name="lidar_sensor" type="lidar">
      <always_on>true</always_on>
      <update_rate>30</update_rate>
      <lidar>
        <scan>
          <horizontal>
            <samples>360</samples>
            <resolution>1</resolution>
            <min_angle>-3.14</min_angle>
            <max_angle>3.14</max_angle>
          </horizontal>
        </scan>
        <range>
          <min>0.1</min>
          <max>10.0</max>
          <resolution>0.01</resolution>
        </range>
      </lidar>
    </sensor>
  </gazebo>

  <!-- Downward-Facing Sonar on base_link -->
  <gazebo reference="base_link">
    <sensor name="sonar_sensor" type="ray">
      <always_on>true</always_on>
      <update_rate>20</update_rate>
      <ray>
        <scan>
          <horizontal>
            <samples>1</samples>
            <min_angle>0</min_angle>
            <max_angle>0</max_angle>
          </horizontal>
        </scan>
        <range>
          <min>0.2</min>
          <max>5.0</max>
          <resolution>0.01</resolution>
        </range>
      </ray>
    </sensor>
    <sensor name="barometer_sensor" type="air_pressure">
      <always_on>true</always_on>
      <update_rate>20</update_rate>
      <air_pressure>
        <noise>
          <type>gaussian</type>
          <mean>0</mean>
          <stddev>0.02</stddev>
        </noise>
      </air_pressure>
    </sensor>
  </gazebo>

</robot>